Workbook

Sheet PLANEACION
A1: Descripción | B1: SKU | C1: Lote | D1: Finca | E1: Destino | F1: NIVEL CRITICO | G1: Cantidad | H1: Pallets | I1: Fecha de proceso | J1: SEMANA | K1: DIAS TRANSITO | L1: HORAS TRANSITO | M1: FECHA CITA | N1: OV OM
A2: =IF('Consulta1'!A4094="","",'Consulta1'!A4094) -> Chanitos Premium EUA Tarima Americana | B2: =IF('Consulta1'!B4094="","",'Consulta1'!B4094) -> CPR01104 | C2: =IF('Consulta1'!C4094="","",'Consulta1'!C4094) -> A04084-392109-1 | D2: =IF('Consulta1'!D4094="","",'Consulta1'!D4094) -> A04 084 Lisboa | E2: =IF('Consulta1'!E4094="","",'Consulta1'!E4094) -> McAllen | F2: =+IF(E2="","",VLOOKUP(E2,CATALOGO!G:L,6,0)) -> 8 | G2: =IF('Consulta1'!F4094="","",'Consulta1'!F4094) -> 480 | H2: =IF('Consulta1'!G4094="","",'Consulta1'!G4094) -> 10 | I2: =IF('Consulta1'!H4094="","",'Consulta1'!H4094) -> 46286 | J2: =+IF(E2="","",WEEKNUM(I2)) -> 39 | K2: =+IF(E2="","",VLOOKUP(E2,CATALOGO!G:I,2,0)) -> 3 | L2: =+IF(E2="","",VLOOKUP(E2,CATALOGO!G:I,3,0)) -> 72 | M2: =IF('Consulta1'!I4094="","",'Consulta1'!I4094) -> 46290 | N2: =IF('Consulta1'!J4094="","",'Consulta1'!J4094) -> 44551
A3: =IF('Consulta1'!A4095="","",'Consulta1'!A4095) -> Chanitos Premium EUA Tarima Americana | B3: =IF('Consulta1'!B4095="","",'Consulta1'!B4095) -> CPR01104 | C3: =IF('Consulta1'!C4095="","",'Consulta1'!C4095) -> A04084-392109-1 | D3: =IF('Consulta1'!D4095="","",'Consulta1'!D4095) -> A04 084 Lisboa | E3: =IF('Consulta1'!E4095="","",'Consulta1'!E4095) -> McAllen | F3: =+IF(E3="","",VLOOKUP(E3,CATALOGO!G:L,6,0)) -> 8 | G3: =IF('Consulta1'!F4095="","",'Consulta1'!F4095) -> 240 | H3: =IF('Consulta1'!G4095="","",'Consulta1'!G4095) -> 5 | I3: =IF('Consulta1'!H4095="","",'Consulta1'!H4095) -> 46286 | J3: =+IF(E3="","",WEEKNUM(I3)) -> 39 | K3: =+IF(E3="","",VLOOKUP(E3,CATALOGO!G:I,2,0)) -> 3 | L3: =+IF(E3="","",VLOOKUP(E3,CATALOGO!G:I,3,0)) -> 72 | M3: =IF('Consulta1'!I4095="","",'Consulta1'!I4095) -> 46290 | N3: =IF('Consulta1'!J4095="","",'Consulta1'!J4095)
A4: =IF('Consulta1'!A4096="","",'Consulta1'!A4096) -> Chanitos Premium Tarima Chep | B4: =IF('Consulta1'!B4096="","",'Consulta1'!B4096) -> CPR01102 | C4: =IF('Consulta1'!C4096="","",'Consulta1'!C4096) -> A01001-392109-1 | D4: =IF('Consulta1'!D4096="","",'Consulta1'!D4096) -> A01 001 Marbella | E4: =IF('Consulta1'!E4096="","",'Consulta1'!E4096) -> QRO | F4: =+IF(E4="","",VLOOKUP(E4,CATALOGO!G:L,6,0)) -> 3 | G4: =IF('Consulta1'!F4096="","",'Consulta1'!F4096) -> 1104 | H4: =IF('Consulta1'!G4096="","",'Consulta1'!G4096) -> 23 | I4: =IF('Consulta1'!H4096="","",'Consulta1'!H4096) -> 46286 | J4: =+IF(E4="","",WEEKNUM(I4)) -> 39 | K4: =+IF(E4="","",VLOOKUP(E4,CATALOGO!G:I,2,0)) -> 1.5 | L4: =+IF(E4="","",VLOOKUP(E4,CATALOGO!G:I,3,0)) -> 36 | M4: =IF('Consulta1'!I4096="","",'Consulta1'!I4096) -> 46290 | N4: =IF('Consulta1'!J4096="","",'Consulta1'!J4096) -> 44907
A5: =IF('Consulta1'!A4097="","",'Consulta1'!A4097) -> Chanitos Premium Tarima Chep | B5: =IF('Consulta1'!B4097="","",'Consulta1'!B4097) -> CPR01102 | C5: =IF('Consulta1'!C4097="","",'Consulta1'!C4097) -> A01001-392109-1 | D5: =IF('Consulta1'!D4097="","",'Consulta1'!D4097) -> A01 001 Marbella | E5: =IF('Consulta1'!E4097="","",'Consulta1'!E4097) -> CEDA | F5: =+IF(E5="","",VLOOKUP(E5,CATALOGO!G:L,6,0)) -> 0 | G5: =IF('Consulta1'!F4097="","",'Consulta1'!F4097) -> 144 | H5: =IF('Consulta1'!G4097="","",'Consulta1'!G4097) -> 3 | I5: =IF('Consulta1'!H4097="","",'Consulta1'!H4097) -> 46286 | J5: =+IF(E5="","",WEEKNUM(I5)) -> 39 | K5: =+IF(E5="","",VLOOKUP(E5,CATALOGO!G:I,2,0)) -> 1.5 | L5: =+IF(E5="","",VLOOKUP(E5,CATALOGO!G:I,3,0)) -> 36 | M5: =IF('Consulta1'!I4097="","",'Consulta1'!I4097) -> 46288 | N5: =IF('Consulta1'!J4097="","",'Consulta1'!J4097) -> 0
A6: =IF('Consulta1'!A4098="","",'Consulta1'!A4098) -> Chanitos Premium Granel | B6: =IF('Consulta1'!B4098="","",'Consulta1'!B4098) -> CPR01101 | C6: =IF('Consulta1'!C4098="","",'Consulta1'!C4098) -> A01001-392109-1 | D6: =IF('Consulta1'!D4098="","",'Consulta1'!D4098) -> A01 001 Marbella | E6: =IF('Consulta1'!E4098="","",'Consulta1'!E4098) -> CEDA | F6: =+IF(E6="","",VLOOKUP(E6,CATALOGO!G:L,6,0)) -> 0 | G6: =IF('Consulta1'!F4098="","",'Consulta1'!F4098) -> 225 | H6: =IF('Consulta1'!G4098="","",'Consulta1'!G4098) -> Granel | I6: =IF('Consulta1'!H4098="","",'Consulta1'!H4098) -> 46286 | J6: =+IF(E6="","",WEEKNUM(I6)) -> 39 | K6: =+IF(E6="","",VLOOKUP(E6,CATALOGO!G:I,2,0)) -> 1.5 | L6: =+IF(E6="","",VLOOKUP(E6,CATALOGO!G:I,3,0)) -> 36 | M6: =IF('Consulta1'!I4098="","",'Consulta1'!I4098) -> 46288 | N6: =IF('Consulta1'!J4098="","",'Consulta1'!J4098) -> 0
A7: =IF('Consulta1'!A4099="","",'Consulta1'!A4099) -> Chanitos Cha Cha Cha (2da) Granel | B7: =IF('Consulta1'!B4099="","",'Consulta1'!B4099) -> CSA04120 | C7: =IF('Consulta1'!C4099="","",'Consulta1'!C4099) -> A01001-392109-4 | D7: =IF('Consulta1'!D4099="","",'Consulta1'!D4099) -> A01 001 Marbella | E7: =IF('Consulta1'!E4099="","",'Consulta1'!E4099) -> CEDA | F7: =+IF(E7="","",VLOOKUP(E7,CATALOGO!G:L,6,0)) -> 0 | G7: =IF('Consulta1'!F4099="","",'Consulta1'!F4099) -> 60 | H7: =IF('Consulta1'!G4099="","",'Consulta1'!G4099) -> Granel | I7: =IF('Consulta1'!H4099="","",'Consulta1'!H4099) -> 46286 | J7: =+IF(E7="","",WEEKNUM(I7)) -> 39 | K7: =+IF(E7="","",VLOOKUP(E7,CATALOGO!G:I,2,0)) -> 1.5 | L7: =+IF(E7="","",VLOOKUP(E7,CATALOGO!G:I,3,0)) -> 36 | M7: =IF('Consulta1'!I4099="","",'Consulta1'!I4099) -> 46288 | N7: =IF('Consulta1'!J4099="","",'Consulta1'!J4099) -> 0
A8: =IF('Consulta1'!A4100="","",'Consulta1'!A4100) -> Chanitos Manitas Granel | B8: =IF('Consulta1'!B4100="","",'Consulta1'!B4100) -> CMN05123 | C8: =IF('Consulta1'!C4100="","",'Consulta1'!C4100) -> A01001-392109-3 | D8: =IF('Consulta1'!D4100="","",'Consulta1'!D4100) -> A01 001 Marbella | E8: =IF('Consulta1'!E4100="","",'Consulta1'!E4100) -> CEDA | F8: =+IF(E8="","",VLOOKUP(E8,CATALOGO!G:L,6,0)) -> 0 | G8: =IF('Consulta1'!F4100="","",'Consulta1'!F4100) -> 29 | H8: =IF('Consulta1'!G4100="","",'Consulta1'!G4100) -> Granel | I8: =IF('Consulta1'!H4100="","",'Consulta1'!H4100) -> 46286 | J8: =+IF(E8="","",WEEKNUM(I8)) -> 39 | K8: =+IF(E8="","",VLOOKUP(E8,CATALOGO!G:I,2,0)) -> 1.5 | L8: =+IF(E8="","",VLOOKUP(E8,CATALOGO!G:I,3,0)) -> 36 | M8: =IF('Consulta1'!I4100="","",'Consulta1'!I4100) -> 46288 | N8: =IF('Consulta1'!J4100="","",'Consulta1'!J4100) -> 0
A9: =IF('Consulta1'!A4101="","",'Consulta1'!A4101) -> Chanitos Cha Cha Cha (DS) Granel | B9: =IF('Consulta1'!B4101="","",'Consulta1'!B4101) -> CDS04122 | C9: =IF('Consulta1'!C4101="","",'Consulta1'!C4101) -> A01001-392109-1 | D9: =IF('Consulta1'!D4101="","",'Consulta1'!D4101) -> A01 001 Marbella | E9: =IF('Consulta1'!E4101="","",'Consulta1'!E4101) -> CEDA | F9: =+IF(E9="","",VLOOKUP(E9,CATALOGO!G:L,6,0)) -> 0 | G9: =IF('Consulta1'!F4101="","",'Consulta1'!F4101) -> 70 | H9: =IF('Consulta1'!G4101="","",'Consulta1'!G4101) -> Granel | I9: =IF('Consulta1'!H4101="","",'Consulta1'!H4101) -> 46286 | J9: =+IF(E9="","",WEEKNUM(I9)) -> 39 | K9: =+IF(E9="","",VLOOKUP(E9,CATALOGO!G:I,2,0)) -> 1.5 | L9: =+IF(E9="","",VLOOKUP(E9,CATALOGO!G:I,3,0)) -> 36 | M9: =IF('Consulta1'!I4101="","",'Consulta1'!I4101) -> 46288 | N9: =IF('Consulta1'!J4101="","",'Consulta1'!J4101) -> 0
A10: =IF('Consulta1'!A4102="","",'Consulta1'!A4102) -> Chanitos Premium Tarima Chep | B10: =IF('Consulta1'!B4102="","",'Consulta1'!B4102) -> CPR01102 | C10: =IF('Consulta1'!C4102="","",'Consulta1'!C4102) -> A01002-392109-1 | D10: =IF('Consulta1'!D4102="","",'Consulta1'!D4102) -> A01 002 Fortaleza | E10: =IF('Consulta1'!E4102="","",'Consulta1'!E4102) -> SMO | F10: =+IF(E10="","",VLOOKUP(E10,CATALOGO!G:L,6,0)) -> 4 | G10: =IF('Consulta1'!F4102="","",'Consulta1'!F4102) -> 144 | H10: =IF('Consulta1'!G4102="","",'Consulta1'!G4102) -> 3 | I10: =IF('Consulta1'!H4102="","",'Consulta1'!H4102) -> 46286 | J10: =+IF(E10="","",WEEKNUM(I10)) -> 39 | K10: =+IF(E10="","",VLOOKUP(E10,CATALOGO!G:I,2,0)) -> 1.5 | L10: =+IF(E10="","",VLOOKUP(E10,CATALOGO!G:I,3,0)) -> 36 | M10: =IF('Consulta1'!I4102="","",'Consulta1'!I4102) -> 46289 | N10: =IF('Consulta1'!J4102="","",'Consulta1'!J4102) -> OV ND para ese SKU vs esa cantidad
A11: =IF('Consulta1'!A4103="","",'Consulta1'!A4103) -> Chanitos Premium Tarima Chep | B11: =IF('Consulta1'!B4103="","",'Consulta1'!B4103) -> CPR01102 | C11: =IF('Consulta1'!C4103="","",'Consulta1'!C4103) -> A01002-392109-1 | D11: =IF('Consulta1'!D4103="","",'Consulta1'!D4103) -> A01 002 Fortaleza | E11: =IF('Consulta1'!E4103="","",'Consulta1'!E4103) -> SMO | F11: =+IF(E11="","",VLOOKUP(E11,CATALOGO!G:L,6,0)) -> 4 | G11: =IF('Consulta1'!F4103="","",'Consulta1'!F4103) -> 96 | H11: =IF('Consulta1'!G4103="","",'Consulta1'!G4103) -> 2 | I11: =IF('Consulta1'!H4103="","",'Consulta1'!H4103) -> 46286 | J11: =+IF(E11="","",WEEKNUM(I11)) -> 39 | K11: =+IF(E11="","",VLOOKUP(E11,CATALOGO!G:I,2,0)) -> 1.5 | L11: =+IF(E11="","",VLOOKUP(E11,CATALOGO!G:I,3,0)) -> 36 | M11: =IF('Consulta1'!I4103="","",'Consulta1'!I4103) -> 46291 | N11: =IF('Consulta1'!J4103="","",'Consulta1'!J4103) -> 44337
A12: =IF('Consulta1'!A4104="","",'Consulta1'!A4104) -> Chanitos Organic Banded Market Side Mexico | B12: =IF('Consulta1'!B4104="","",'Consulta1'!B4104) -> CRG07128 | C12: =IF('Consulta1'!C4104="","",'Consulta1'!C4104) -> A01002-392109-1 | D12: =IF('Consulta1'!D4104="","",'Consulta1'!D4104) -> A01 002 Fortaleza | E12: =IF('Consulta1'!E4104="","",'Consulta1'!E4104) -> QRO | F12: =+IF(E12="","",VLOOKUP(E12,CATALOGO!G:L,6,0)) -> 3 | G12: =IF('Consulta1'!F4104="","",'Consulta1'!F4104) -> 48 | H12: =IF('Consulta1'!G4104="","",'Consulta1'!G4104) -> 1 | I12: =IF('Consulta1'!H4104="","",'Consulta1'!H4104) -> 46286 | J12: =+IF(E12="","",WEEKNUM(I12)) -> 39 | K12: =+IF(E12="","",VLOOKUP(E12,CATALOGO!G:I,2,0)) -> 1.5 | L12: =+IF(E12="","",VLOOKUP(E12,CATALOGO!G:I,3,0)) -> 36 | M12: =IF('Consulta1'!I4104="","",'Consulta1'!I4104) -> 46290 | N12: =IF('Consulta1'!J4104="","",'Consulta1'!J4104) -> 44907
A13: =IF('Consulta1'!A4105="","",'Consulta1'!A4105) -> Chanitos Organic Banded Market Side Mexico | B13: =IF('Consulta1'!B4105="","",'Consulta1'!B4105) -> CRG07128 | C13: =IF('Consulta1'!C4105="","",'Consulta1'!C4105) -> A01002-392109-1 | D13: =IF('Consulta1'!D4105="","",'Consulta1'!D4105) -> A01 002 Fortaleza | E13: =IF('Consulta1'!E4105="","",'Consulta1'!E4105) -> MTY | F13: =+IF(E13="","",VLOOKUP(E13,CATALOGO!G:L,6,0)) -> 2 | G13: =IF('Consulta1'!F4105="","",'Consulta1'!F4105) -> 48 | H13: =IF('Consulta1'!G4105="","",'Consulta1'!G4105) -> 1 | I13: =IF('Consulta1'!H4105="","",'Consulta1'!H4105) -> 46286 | J13: =+IF(E13="","",WEEKNUM(I13)) -> 39 | K13: =+IF(E13="","",VLOOKUP(E13,CATALOGO!G:I,2,0)) -> 2.5 | L13: =+IF(E13="","",VLOOKUP(E13,CATALOGO!G:I,3,0)) -> 60 | M13: =IF('Consulta1'!I4105="","",'Consulta1'!I4105) -> 46290 | N13: =IF('Consulta1'!J4105="","",'Consulta1'!J4105) -> 45214
... A1001: =IF('Consulta1'!A5093="","",'Consulta1'!A5093) | B1001: =IF('Consulta1'!B5093="","",'Consulta1'!B5093) | C1001: =IF('Consulta1'!C5093="","",'Consulta1'!C5093) | D1001: =IF('Consulta1'!D5093="","",'Consulta1'!D5093) | E1001: =IF('Consulta1'!E5093="","",'Consulta1'!E5093) | F1001: =+IF(E1001="","",VLOOKUP(E1001,CATALOGO!G:L,6,0)) | G1001: =IF('Consulta1'!F5093="","",'Consulta1'!F5093) | H1001: =IF('Consulta1'!G5093="","",'Consulta1'!G5093) | I1001: =IF('Consulta1'!H5093="","",'Consulta1'!H5093) | J1001: =+IF(E1001="","",WEEKNUM(I1001)) | K1001: =+IF(E1001="","",VLOOKUP(E1001,CATALOGO!G:I,2,0)) | L1001: =+IF(E1001="","",VLOOKUP(E1001,CATALOGO!G:I,3,0)) | M1001: =IF('Consulta1'!I5093="","",'Consulta1'!I5093) | N1001: =IF('Consulta1'!J5093="","",'Consulta1'!J5093)

Sheet Consulta1
A1: Descripción | B1: SKU | C1: Lote | D1: Finca | E1: Destino | F1: Cantidad | G1: Pallets | H1: Fecha de proceso | I1: FECHA CITA | J1: OV OM | K1: Llave_Base_Consulta | L1: Ocurrencia_Consulta | M1: Llave_Embarque_Consulta | N1: Archivo_Origen
A2: Chanitos Cha Cha Cha 22XU CP26 Mar Kodawari | B2: CPR03117 | C2: A01001-012912-1 | D2: A01 001 Marbella | F2: 756 | G2: 14 | H2: 46020 | I2: 46024 | J2: 16667 | N2: Programa Embarques 2026 S-01.xlsx
A3: Chanitos Cha Cha Cha 22XU CP34 Mar Kodawari | B3: CPR03119 | C3: A01001-012912-1 | D3: A01 001 Marbella | F3: 324 | G3: 6 | H3: 46020 | I3: 46024 | J3: 16667 | N3: Programa Embarques 2026 S-01.xlsx
A4: Chanitos Premium Granel | B4: CPR01101 | C4: A01001-012912-1 | D4: A01 001 Marbella | F4: 152 | G4: Granel | H4: 46020 | I4: 46022 | N4: Programa Embarques 2026 S-01.xlsx
A5: Chanitos Cha Cha Cha (2da) Granel | B5: CSA04120 | C5: A01001-012912-4 | D5: A01 001 Marbella | F5: 88 | G5: Granel | H5: 46020 | I5: 46022 | N5: Programa Embarques 2026 S-01.xlsx
A6: Chanitos Manitas Granel | B6: CMN05123 | C6: A01001-012912-3 | D6: A01 001 Marbella | F6: 2 | G6: Granel | H6: 46020 | I6: 46022 | N6: Programa Embarques 2026 S-01.xlsx
A7: Chanitos Cha Cha Cha (DS) Granel | B7: CDS04122 | C7: A01001-012912-5 | D7: A01 001 Marbella | F7: 40 | G7: Granel | H7: 46020 | I7: 46022 | N7: Programa Embarques 2026 S-01.xlsx
A8: Chanitos Premium Tarima Chep | B8: CPR01102 | C8: A04084-012912-1 | D8: A04 084 Lisboa | F8: 1008 | G8: 21 | H8: 46020 | I8: 46024 | J8: 16130 | N8: Programa Embarques 2026 S-01.xlsx
A9: Chanitos Premium Tarima Chep | B9: CPR01102 | C9: A01002-012912-1 | D9: A01 002 Fortaleza | F9: 864 | G9: 18 | H9: 46020 | I9: 46024 | J9: 16093 | N9: Programa Embarques 2026 S-01.xlsx
A10: Chanitos Premium Tarima Americana | B10: CPR01103 | C10: A11045-012912-1 | D10: A11 045 Sector Mazatan | F10: 960 | G10: 20 | H10: 46020 | I10: 46027 | J10: 16315 | N10: Programa Embarques 2026 S-01.xlsx
A11: Chanitos Premium Tarima Americana | B11: CPR01103 | C11: A11092-012912-1 | D11: A11 092 Composta | F11: 624 | G11: 13 | H11: 46020 | I11: 46027 | J11: 16316 | N11: Programa Embarques 2026 S-01.xlsx
A12: Chanitos Premium Tarima Chep | B12: CPR01102 | C12: A01002-012912-1 | D12: A01 002 Fortaleza | F12: 144 | G12: 3 | H12: 46020 | I12: 46024 | J12: 16130 | N12: Programa Embarques 2026 S-01.xlsx
A13: Chanitos Premium Tarima Chep | B13: CPR01102 | C13: A01002-012912-1 | D13: A01 002 Fortaleza | F13: 48 | G13: 2 | H13: 46020 | I13: 46022 | N13: Programa Embarques 2026 S-01.xlsx
A14: Chanitos Premium Granel | B14: CPR01101 | C14: A01002-012912-1 | D14: A01 002 Fortaleza | F14: 16 | G14: Granel | H14: 46020 | I14: 46022 | N14: Programa Embarques 2026 S-01.xlsx
A15: Chanitos Premium Tarima Chep | B15: CPR01102 | C15: A01004-012912-1 | D15: A01 004 La Ceiba | F15: 1056 | G15: 22 | H15: 46020 | I15: 46022 | N15: Programa Embarques 2026 S-01.xlsx
A16: Chanitos Premium Granel | B16: CPR01101 | C16: A01004-012912-1 | D16: A01 004 La Ceiba | F16: 15 | G16: Granel | H16: 46020 | I16: 46022 | N16: Programa Embarques 2026 S-01.xlsx
A17: Chanitos Snack | B17: CDS06124 | C17: A01002-012912-1 | D17: A01 002 Fortaleza | F17: 235 | G17: 2 | H17: 46020 | I17: 46022 | N17: Programa Embarques 2026 S-01.xlsx
A18: Chanitos Premium Tarima Chep | B18: CPR01102 | C18: A01001-013012-1 | D18: A01 001 Marbella | F18: 1152 | G18: 24 | H18: 46021 | I18: 46025 | J18: 16314 | N18: Programa Embarques 2026 S-01.xlsx
A19: Chanitos Premium Granel | B19: CPR01101 | C19: A01001-013012-1 | D19: A01 001 Marbella | F19: 108 | G19: Granel | H19: 46021 | I19: 46022 | N19: Programa Embarques 2026 S-01.xlsx
A20: Chanitos Cha Cha Cha (2da) Granel | B20: CSA04120 | C20: A01001-013012-4 | D20: A01 001 Marbella | F20: 88 | G20: Granel | H20: 46021 | I20: 46023 | N20: Programa Embarques 2026 S-01.xlsx
A21: Chanitos Manitas Granel | B21: CMN05123 | C21: A01001-013012-3 | D21: A01 001 Marbella | F21: 12 | G21: Granel | H21: 46021 | I21: 46023 | N21: Programa Embarques 2026 S-01.xlsx
A22: Chanitos Cha Cha Cha (DS) Granel | B22: CDS04122 | C22: A01001-013012-5 | D22: A01 001 Marbella | F22: 62 | G22: Granel | H22: 46021 | I22: 46023 | N22: Programa Embarques 2026 S-01.xlsx
A23: Chanitos Organic Banded Market Side Mexico | B23: CRG07128 | C23: A01002-013012-1 | D23: A01 002 Fortaleza | F23: 288 | G23: 6 | H23: 46021 | I23: 46024 | J23: 16098 | N23: Programa Embarques 2026 S-01.xlsx
A24: Chanitos Premium Tarima Chep | B24: CPR01102 | C24: A04084-013012-1 | D24: A04 084 Lisboa | F24: 1056 | G24: 22 | H24: 46021 | I24: 46027 | J24: 16681 | N24: Programa Embarques 2026 S-01.xlsx
A25: Chanitos Premium Tarima Chep | B25: CPR01102 | C25: A01002-013012-1 | D25: A01 002 Fortaleza | F25: 96 | G25: 2 | H25: 46021 | I25: 46027 | J25: 16681 | N25: Programa Embarques 2026 S-01.xlsx
A26: Chanitos Premium Tarima Americana | B26: CPR01103 | C26: A01002-013012-1 | D26: A01 002 Fortaleza | F26: 816 | G26: 17 | H26: 46021 | I26: 46027 | J26: 16315 | N26: Programa Embarques 2026 S-01.xlsx
A27: Chanitos Plantain 20Kg Tarima Americana | B27: CPL08134 | C27: A26077-013012-1 | D27: A26 077 Dorado Nuevo | F27: 144 | G27: 3 | H27: 46021 | I27: 46027 | J27: 16315 | N27: Programa Embarques 2026 S-01.xlsx
A28: Chanitos Plantain 20Kg Tarima Americana | B28: CPL08134 | C28: A26077-013012-1 | D28: A26 077 Dorado Nuevo | F28: 144 | G28: 3 | H28: 46021 | I28: 46031 | J28: 16840 | N28: Programa Embarques 2026 S-01.xlsx
A29: Chanitos Plantain 20Kg Tarima Chep | B29: CPL08141 | C29: A26077-013012-1 | D29: A26 077 Dorado Nuevo | F29: 288 | G29: 6 | H29: 46021 | I29: 46024 | N29: Programa Embarques 2026 S-01.xlsx
A30: Chanitos Premium Tarima Americana | B30: CPR01103 | C30: A01004-013012-1 | D30: A01 004 La Ceiba | F30: 960 | G30: 20 | H30: 46021 | I30: 46027 | J30: 16316 | N30: Programa Embarques 2026 S-01.xlsx
A31: Chanitos Premium Granel | B31: CPR01101 | C31: A01004-013012-1 | D31: A01 004 La Ceiba | F31: 5 | G31: Granel | H31: 46021 | I31: 46022 | N31: Programa Embarques 2026 S-01.xlsx
A32: Chanitos Premium Tarima Americana | B32: CPR01103 | C32: A11087-013012-1 | D32: A11 087 19 de Abril | F32: 336 | G32: 7 | H32: 46021 | I32: 46027 | J32: 16316 | N32: Programa Embarques 2026 S-01.xlsx
A33: Chanitos Plantain 50lb Tarima Americana | B33: CPL08133 | C33: A27073-013012-1 | D33: A27 073 Plantacion | F33: 840 | G33: 20 | H33: 46021 | I33: 46024 | J33: 15769 | N33: Programa Embarques 2026 S-01.xlsx
A34: Chanitos Snack | B34: CDS06124 | C34: A01002-013012-1 | D34: A01 002 Fortaleza | F34: 109 | G34: 1 | H34: 46021 | I34: 46023 | N34: Programa Embarques 2026 S-01.xlsx
A35: Chanitos Premium Granel | B35: CPR01101 | C35: A01002-013012-1 | D35: A01 002 Fortaleza | F35: 40 | G35: Granel | H35: 46021 | I35: 46022 | N35: Programa Embarques 2026 S-01.xlsx
A36: Chanitos Premium Tarima Chep | B36: CPR01102 | C36: A01002-013012-1 | D36: A01 002 Fortaleza | F36: 192 | G36: 4 | H36: 46021 | I36: 46023 | N36: Programa Embarques 2026 S-01.xlsx
A37: Chanitos Plantain 50lb Tarima Americana | B37: CPL08133 | C37: A27073-010201-1 | D37: A27 073 Plantacion | F37: 1008 | G37: 24 | H37: 46024 | I37: 46031 | J37: 16104 | N37: Programa Embarques 2026 S-01.xlsx
A38: Chanitos Snack | B38: CDS06124 | C38: A01002-010201-1 | D38: A01 002 Fortaleza | F38: 209 | G38: 2 | H38: 46024 | I38: 46025 | N38: Programa Embarques 2026 S-01.xlsx
A39: Chanitos Premium Tarima Chep | B39: CPR01102 | C39: A01001-010201-1 | D39: A01 001 Marbella | F39: 1200 | G39: 25 | H39: 46024 | I39: 46027 | N39: Programa Embarques 2026 S-01.xlsx
A40: Chanitos Premium Granel | B40: CPR01101 | C40: A01001-010201-1 | D40: A01 001 Marbella | F40: 4 | G40: Granel | H40: 46024 | I40: 46026 | N40: Programa Embarques 2026 S-01.xlsx
...

Sheet UBICACIONES
A1: Trazabilidad de finca | B1: Domicilio | C1: Estado | D1: Municipio | E1: Codigo postal | F1: Coordenadas | G1: Link | H1: Destinos
A2: PREENFRIO NELLY | B2: Plan de Ayala | C2: Chiapas | D2: Huehuetan | E2: 30670 | F2: 14°59'48.9"N 92°29'52.8"W | G2: https://goo.gl/maps/C1cgsvYkCYKNJPny6
A3: PREENFRIO FORTALEZA | B3: Colonia Marta R. Gomez | C3: Chiapas | D3: Mazatan | E3: 30650 | F3: 14°57'15.3"N 92°26'59.0"W | G3: https://goo.gl/maps/fnW8DDkT3wNtEXeSA
A4: A01 001 Marbella | B4: Carretera a Jaritas Km. 13 | C4: Chiapas | D4: Tapachula | E4: 30846 | F4: 14°41'01.6"N 92°17'06.9"W | G4: https://goo.gl/maps/qGeGDXzmmymVyzLP9 | H4: Japón
A5: A01 002 Fortaleza | B5: Colonia Marta R. Gomez | C5: Chiapas | D5: Mazatan | E5: 30650 | F5: 14°57'15.3"N 92°26'59.0"W | G5: https://goo.gl/maps/fnW8DDkT3wNtEXeSA
A6: A01 003 Doña Nelly | B6: Plan de Ayala | C6: Chiapas | D6: Huehuetan | E6: 30670 | F6: 14°59'48.9"N 92°29'52.8"W | G6: https://goo.gl/maps/C1cgsvYkCYKNJPny6
A7: A01 004 La Ceiba | B7: Guamuchal | C7: Chiapas | D7: Huehuetan | E7: 30673 | F7: 14°59'11.9"N 92°30'06.8"W | G7: https://goo.gl/maps/gNwRwT3qCacQ9pMt8
A8: A04 005 La Gloria | B8: Barra de Cahoacan | C8: Chiapas | D8: Suchiate | E8: 30837 | F8: 14°38'20.2"N 92°18'48.1"W | G8: https://goo.gl/maps/4aw6M19uK4XBNera9
A9: A08 006 San Joaquin | B9: Rancho Don Ramon | C9: Chiapas | D9: Suchiate | E9: 30847 | F9: 14°37'00.0"N 92°13'15.2"W | G9: https://goo.gl/maps/3T8XwxYkNNWHompB7
A10: A02 007 Hydro Marte R Gomez | B10: Colonia Marta R. Gomez | C10: Chiapas | D10: Mazatan | E10: 30650 | F10: 14°55'13.7"N 92°27'15.4"W | G10: https://goo.gl/maps/AAM9qnwxs3bxE34W7
A11: A02 008 La Joya | B11: Rancheria Paloma Blanca | C11: Chiapas | D11: Acapetahua | E11: 30583 | F11: 15°18'31.1"N 92°45'06.1"W | G11: https://goo.gl/maps/XvfzqdkZQYTYc8RP8
A12: A02 009 Las Lomas | B12: Ejido Jiquilpan | C12: Chiapas | D12: Acapetahua | E12: 30583 | F12: 15°20'35.2"N 92°48'31.1"W | G12: https://goo.gl/maps/m7xMRRD56wuNJTsN6
A13: A08 010 Las Flores | B13: Suchiate | C13: Chiapas | D13: Suchiate | E13: 30840 | F13: 14°37'29.6"N 92°14'14.1"W | G13: https://goo.gl/maps/F7kNcEaYeHMMGVqv8
A14: A02 011 Herradura del carmen | B14: Rancheria Las Trancas | C14: Chiapas | D14: Mazatan | E14: 30820 | F14: 14°54'57.3"N 92°24'24.1"W | G14: https://goo.gl/maps/8MhTkiqK1NEpgPz99
A15: A02 012 Thomas | B15: Rancheria Canton Genova | C15: Chiapas | D15: Suchiate | E15: 30800 | F15: 14°38'33.6"N 92°11'54.1"W | G15: https://goo.gl/maps/KtztzUgWgS8bmNGD8
A16: A02 013 Marigabriela 1 | B16: Ejido Jesus | C16: Chiapas | D16: Suchiate | E16: 30844 | F16: 14°38'34.7"N 92°11'04.9"W | G16: https://goo.gl/maps/gGd8TGPRhwRBEgwD7
... A26: A08 023 Las Eloisas | B26: Rancho Leoncillos | C26: Chiapas | D26: Tapachula | E26: 30832 | F26: 14°45'45.9"N 92°23'47.9"W | G26: https://goo.gl/maps/DG8BsFRpcQPzaEzh7
A27: A02 024 no usar El Cuerudo | C27: Chiapas | D27: Tapachula
A28: A03 025 Bondad | B28: Altamira | C28: Chiapas | D28: Tapachula | E28: 30814 | F28: 14°40'39.5"N 92°17'37.8"W | G28: https://goo.gl/maps/PphkbMkuv1AH61iV6
A29: A03 026 Santa Fe | B29: La Herradura | C29: Chiapas | D29: Suchiate | E29: 30844 | F29: 14°34'35.0"N 92°13'00.3"W | G29: https://maps.app.goo.gl/shQUvUBQ71mZEDyE9
A30: A03 027 El Cahua | B30: La Innominada | C30: Chiapas | D30: Tapachula | E30: 30838 | F30: 14°39'38.6"N 92°17'03.3"W | G30: https://goo.gl/maps/UD9VxJeq7R3LSwZj7
A31: A03 028 Romina | B31: Benito Juarez | C31: Chiapas | D31: Tapachula | E31: 30790 | F31: 14°38'30.0"N 92°17'02.8"W | G31: https://goo.gl/maps/tK1iT4gHmAHp8ESx7
A32: A03 029 Esmeralda | B32: Cuauhtemoc | C32: Chiapas | D32: Suchiate | E32: 30844 | F32: 14°35'07.6"N 92°13'03.6"W | G32: https://goo.gl/maps/5PxHAbGx6Mt1j4Bv6
A33: A24 030 Venezuela | B33: Rancheria Isleven | C33: Chiapas | D33: Tapachula | E33: 30828 | F33: 14°47'54.2"N 92°17'38.2"W | G33: https://maps.app.goo.gl/D1kHYtV3Q9vsxafm9
A34: A25 031 Vigor | B34: Ejido La Libertad | C34: Chiapas | D34: Suchiate | E34: 30844 | F34: 14°35'29.2"N 92°12'35.1"W | G34: https://goo.gl/maps/QqHfzP5USaXt4oFm6
A35: A24 032 Ojo de agua | B35: Cuatro Caminos | C35: Chiapas | D35: Mazatan | E35: 30650 | F35: 14°53'37.4"N 92°24'31.9"W | G35: https://goo.gl/maps/dFEGsT47n5G8w6DD8
A36: A04 033 Carlota Nava | B36: Finca Santa Teresa | C36: Chiapas | D36: Tapachula | E36: 30807 | F36: 14°50'47.6"N 92°19'33.9"W | G36: https://goo.gl/maps/k3e7xCWrpgYf7pWWA
A37: A04 034 | B37: Los Toros, Estación | C37: Chiapas | D37: Tapachula | E37: 30833 | F37: 14°48'33.1"N 92°19'55.0"W | G37: https://goo.gl/maps/VjxcwdTTfPQVtKEN8
A38: A04 035 Guadalupe Nava | B38: San Juan Cintahuayate | C38: Chiapas | D38: Suchiate | E38: 30840 | F38: 14°45'58.2"N 92°14'39.1"W | G38: https://goo.gl/maps/PCtXDhAWkCfYehYY9
A39: A04 036 Esperanza Nava | B39: Leoncillos | C39: Chiapas | D39: Tapachula | E39: 30832 | F39: 14°47'26.0"N 92°24'52.0"W | G39: https://goo.gl/maps/bqehwq2po61ugXeJA
... A61: A12 058 Tiquisate 2 | B61: San Judas Tadeo | C61: Chiapas | D61: Mazatan | E61: 30837 | F61: 14°50'19.9"N 92°26'41.6"W | G61: https://goo.gl/maps/ZfYCbsRGBJhm13mr6
A62: A13 059 Skarlet | D62: Mazatan
A63: A13 060 Los Angeles | D63: Mazatan
A64: A14 061 Corozal | B64: Poblacion 5 de febrero | C64: Chiapas | D64: Huehuetan | E64: 30656 | F64: 15°00'22.9"N 92°28'29.5"W | G64: https://goo.gl/maps/iVPW93wEVUpUoL919
A65: A14 062 Charly | B65: Santa Monica | C65: Chiapas | D65: Suchiate | E65: 30845 | F65: 14°42'54.4"N 92°09'41.3"W | G65: https://goo.gl/maps/FRyoYUTxMLVmWMFq8
A66: A15 063 Zaragoza | B66: Ignacio Zaragoza | C66: Chiapas | D66: Suchiate | E66: 30845 | F66: 14°44'26.2"N 92°10'15.8"W | G66: https://goo.gl/maps/bFQhTdj4k4rnRjQr9
A67: A16 064 Santa Elena | B67: Pilar Sitala | C67: Chiapas | D67: Mazatan | E67: 30656 | F67: 14°57'02.1"N 92°29'48.5"W | G67: https://goo.gl/maps/xTd632Tk6bUJDZDv5
A68: A17 065 Anvirama | D68: Huehuetan
A69: A18 066 Chaparral | B69: Las Viudas | C69: Chiapas | D69: Suchiate | E69: 30845 | F69: 14°42'46.4"N 92°12'07.5"W | G69: https://goo.gl/maps/j2iMYbYmkfqLxxYo9
A70: A25 067 El Cuerudo GT | B70: El Coquito | C70: Chiapas | D70: Tapachula | E70: 30827 | F70: 14°49'42.4"N 92°22'44.8"W | G70: https://goo.gl/maps/eRVzs5rm2RN8QXhp8
...

Sheet CATALOGO
A1: PREENFRIO NELLY | B1: ALTA | C1: VOLUMEN / CAPACIDAD INSTALADA | F1: CLIENTE | G1: DESTINO | H1: TRÁNSITO (DÍAS) | I1: TRÁNSITO (HRS) | J1: CICLO HORAS FORTALEZA | K1: CICLO HORAS NELLY | L1: CRITICIDAD
A2: PREENFRIO FORTALEZA | B2: NORMAL | C2: POSICIONAMIENTO DE TRANSPORTE | F2: SMART | G2: Cd. Juárez | H2: 4 | I2: 96 | J2: 0.25 | K2: 0.21875 | L2: 1
A3: DIRECTO SIN PREENFRIO | B3: BAJA | C3: EMPAQUE TARDIO | F3: CHANITOS | G3: CEDA | H3: 1.5 | I3: 36 | J3: 0 | K3: 0
C4: FALLA ELECTRICA | F4: CHANITOS | G4: Chihuahua | H4: 3.5 | I4: 84 | J4: 0.3125 | K4: 0.3125 | L4: 9
C5: MANTENIMIENTO CORRECTIVO | F5: CHIQUITA | G5: Chiquita | H5: 1 | I5: 24 | J5: 0 | K5: 0
C6: MANTENIMIENTO PREVENTIVO | F6: CHANITOS | G6: Colima | H6: 2 | I6: 48 | J6: 0 | K6: 0
F7: JAPON | G7: Japon | H7: 2 | I7: 48 | J7: 0 | K7: 0
A8: PREENFRIO | B8: PALLETS | F8: CHANITOS | G8: McAllen | H8: 3 | I8: 72 | J8: 0.20833333 | K8: 0.17708333 | L8: 8
A9: NELLY | B9: 12 | F9: WALMART | G9: MTY | H9: 2.5 | I9: 60 | J9: 0.20833333 | K9: 0.17708333 | L9: 2
A10: FORTALEZA | B10: 10 | F10: SMART | G10: Ciudad Juarez | H10: 4 | I10: 96 | J10: 0.25 | K10: 0.21875 | L10: 1
F11: WALMART | G11: SMO | H11: 1.5 | I11: 36 | J11: 0.20833333 | K11: 0.17708333 | L11: 4
F12: SMART | G12: S-MTY | H12: 3 | I12: 72 | J12: 0.25 | K12: 0.21875 | L12: 1
F13: CHANITOS | G13: Tultitlan | H13: 1.5 | I13: 36 | J13: 0 | K13: 0
F14: CHANITOS | G14: Tulti-CEDA | H14: 1.5 | I14: 36 | J14: 0 | K14: 0
F15: CHANITOS | G15: Tabasco | H15: 1 | I15: 24 | J15: 0 | K15: 0
F16: WALMART | G16: Chalco | H16: 1 | I16: 24 | J16: 0.20833333 | K16: 0.17708333 | L16: 5
F17: WALMART | G17: VSA | H17: 1 | I17: 24 | J17: 0.20833333 | K17: 0.17708333 | L17: 6
F18: WALMART | G18: QRO | H18: 1.5 | I18: 36 | J18: 0.20833333 | K18: 0.17708333 | L18: 3
F19: WALMART | G19: Zumpango | H19: 1.5 | I19: 36 | J19: 0.20833333 | K19: 0.17708333 | L19: 7
